Workbook
Name IQ_CH: 110000
Name IQ_CQ: 5000
Name IQ_CY: 10000
Name IQ_DAILY: 500000
Name IQ_FH: 100000
Name IQ_FQ: 500
Name IQ_FY: 1000
Name IQ_LTM: 2000
Name IQ_MONTH: 15000
Name IQ_NTM: 6000
Name IQ_WEEK: 50000
Name IQ_YTD: 3000

Sheet Staffing_2026
D1: Forecast | E1: Forecast | F1: Forecast | G1: Forecast | H1: Forecast | I1: Forecast | J1: Forecast | K1: Forecast | L1: Forecast | M1: Forecast | N1: Forecast | O1: Forecast
A2: Name | B2: POC | C2: Service | D2: Jan | E2: Feb | F2: Mar | G2: Apr | H2: May | I2: Jun | J2: Jul | K2: Aug | L2: Sep | M2: Oct | N2: Nov | O2: Dec | P2: Total | Q2: Comments | R2: Renewal Confidence | S2: Group | T2: Sub-Group
C3: Staffing | T3: Secured
C4: Staffing | T4: Secured
C5: Staffing | T5: Secured
C6: Staffing | T6: Secured
C7: Staffing | T7: Secured
C8: Staffing | T8: Secured
C9: Staffing | T9: Secured
C10: Staffing | T10: Secured
C11: Staffing | T11: Secured
C12: Staffing | T12: Secured
A13: Subtotal- Secured | D13: =SUM(D3:D12) -> 0 | E13: =SUM(E3:E12) -> 0 | F13: =SUM(F3:F12) -> 0 | G13: =SUM(G3:G12) -> 0 | H13: =SUM(H3:H12) -> 0 | I13: =SUM(I3:I12) -> 0 | J13: =SUM(J3:J12) -> 0 | K13: =SUM(K3:K12) -> 0 | ... P13: =SUM(P3:P12) -> 0
C15: Staffing
C16: Staffing | T16: Projected
C17: Staffing | T17: Projected
C18: Staffing | T18: Projected
C19: Staffing | T19: Projected
C20: Staffing | T20: Projected
C21: Staffing | T21: Projected
C22: Staffing | T22: Projected
C23: Staffing | T23: Projected
C24: Staffing | T24: Projected
C25: Staffing | T25: Projected
C26: Staffing | T26: Projected
A27: Subtotal- Projected | D27: =SUM(D15:D26) -> 0 | E27: =SUM(E15:E26) -> 0 | F27: =SUM(F15:F26) -> 0 | G27: =SUM(G15:G26) -> 0 | H27: =SUM(H15:H26) -> 0 | I27: =SUM(I15:I26) -> 0 | J27: =SUM(J15:J26) -> 0 | K27: =SUM(K15:K26) -> 0 | ... P27: =SUM(P15:P26) -> 0
A29: Grand Total | D29: =+D13+D27 -> 0 | E29: =+E13+E27 -> 0 | F29: =+F13+F27 -> 0 | G29: =+G13+G27 -> 0 | H29: =+H13+H27 -> 0 | I29: =+I13+I27 -> 0 | J29: =+J13+J27 -> 0 | K29: =+K13+K27 -> 0 | ... P29: =+P13+P27 -> 0

Sheet Staffing_Backup_260218
D1: Forecast | E1: Forecast | F1: Forecast | G1: Forecast | H1: Forecast | I1: Forecast | J1: Forecast | K1: Forecast | L1: Forecast | M1: Forecast | N1: Forecast | O1: Forecast
A2: Name | B2: POC | C2: Service | D2: 46023 | E2: 46054 | F2: 46082 | G2: 46113 | H2: 46143 | I2: 46174 | J2: 46204 | K2: 46235 | L2: 46266 | M2: 46296 | N2: 46327 | O2: 46357 | P2: Total Revenue | Q2: Comments | R2: Renewal Confidence | S2: Group | T2: Sub-Group
A3: Staffing
A4: HPE Ami Noss | B4: Manmeet | C4: Staffing | D4: 20276 | E4: 19180 | F4: 23290 | G4: 20139 | H4: 22194 | I4: 22194 | J4: 20276 | K4: 23290 | L4: 20139 | M4: 22194 | N4: 20139 | O4: 19180 | P4: {=SUMPRODUCT((D$1:O$1<>"Margin")*(D$1:O$1<>"Salary_$600")*D4:O4)} -> 252491 | Q4: SOW for renewal has been submitted | R4: 100% | S4: HPE | T4: ds_StaffingT01
A5: HPE Rebecca Wissinger | B5: Manmeet | C5: Staffing | D5: 11100 | E5: 10500 | F5: 12750 | G5: 11025 | H5: 12150 | I5: 12150 | J5: 11100 | K5: 12750 | L5: 11025 | M5: 12150 | N5: 11025 | O5: 10500 | P5: {=SUMPRODUCT((D$1:O$1<>"Margin")*(D$1:O$1<>"Salary_$600")*D5:O5)} -> 138225 | Q5: SOW valid until Oct 31, 2026 | R5: 100% | S5: HPE | T5: ds_StaffingT01
A6: HPE Budget Mgmt | B6: Manmeet | C6: Staffing | D6: 10656 | E6: 10080 | F6: 12240 | G6: 10584 | H6: 11664 | I6: 11664 | J6: 10656 | K6: 12240 | L6: 10584 | M6: 11664 | N6: 10584 | O6: 10080 | P6: {=SUMPRODUCT((D$1:O$1<>"Margin")*(D$1:O$1<>"Salary_$600")*D6:O6)} -> 132696 | Q6: SOW valid until Apr 30, 2026 | R6: 100% | S6: HPE | T6: ds_StaffingT01
A7: HPE Tech Compliance | B7: Manmeet | C7: Staffing | D7: 18216 | E7: 17231 | F7: 20924 | G7: 18093 | H7: 19939 | I7: 19939 | J7: 18216 | K7: 20924 | L7: 18093 | M7: 19939 | N7: 18093 | O7: 17231 | P7: {=SUMPRODUCT((D$1:O$1<>"Margin")*(D$1:O$1<>"Salary_$600")*D7:O7)} -> 226838 | Q7: SOW valid until Jan 31, 2026 | R7: 100% | S7: HPE | T7: ds_StaffingT01
A8: HPE Data Foundation | B8: Manmeet | C8: Staffing | D8: 30932 | E8: 29260 | F8: 35530 | G8: 30723 | H8: 33858 | I8: 33858 | J8: 30932 | K8: 35530 | L8: 30723 | M8: 33858 | N8: 30723 | O8: 29260 | P8: {=SUMPRODUCT((D$1:O$1<>"Margin")*(D$1:O$1<>"Salary_$600")*D8:O8)} -> 385187 | Q8: SOW for renewal has been submitted | R8: 100% | S8: HPE | T8: ds_StaffingT01
A9: HPE Marketing Automation | B9: Manmeet | C9: Staffing | D9: 14060 | E9: 13300 | F9: 16150 | G9: 13965 | H9: 15390 | I9: 15390 | J9: 14060 | K9: 16150 | L9: 13965 | M9: 15390 | N9: 13965 | O9: 13300 | P9: {=SUMPRODUCT((D$1:O$1<>"Margin")*(D$1:O$1<>"Salary_$600")*D9:O9)} -> 175085 | Q9: SOW valid until Jan 31, 2026 | R9: 100% | S9: HPE | T9: ds_StaffingT01
A10: Marvell India Staffing | B10: Sunil/Neeraj | C10: Staffing | D10: 15453 | E10: 14617 | F10: 17750 | G10: 15348 | H10: 16914 | I10: 16914 | J10: 15453 | K10: 17750 | L10: 15348 | M10: 16914 | N10: 15348 | O10: 14617 | P10: {=SUMPRODUCT((D$1:O$1<>"Margin")*(D$1:O$1<>"Salary_$600")*D10:O10)} -> 192426 | Q10: Contract renewed valid till Jan 31, 2026 | R10: 100% | S10: Marvell India | T10: ds_StaffingT01
A11: Azu Solutions | B11: Pankaj/Neeraj | C11: Staffing | P11: {=SUMPRODUCT((D$1:O$1<>"Margin")*(D$1:O$1<>"Salary_$600")*D11:O11)} -> 0 | Q11: SOW valid until Mar 31, 2026 | R11: 100% | S11: AZU Solutions | T11: ds_StaffingT01
A12: Databricks SEO Content Strategist | B12: Manmeet | C12: Staffing | D12: 14208 | E12: 13440 | F12: 16320 | G12: 14112 | H12: 15552 | I12: 15552 | J12: 14208 | K12: 16320 | L12: 1536 | M12: 0 | N12: 0 | O12: 0 | P12: {=SUMPRODUCT((D$1:O$1<>"Margin")*(D$1:O$1<>"Salary_$600")*D12:O12)} -> 121248 | Q12: SOW valid until Feb 28, 2026 | R12: 100% | S12: Databricks | T12: ds_StaffingT01
A13: JSG | B13: Wendy | C13: Staffing | D13: 4588 | E13: 4340 | F13: 5270 | G13: 4557 | H13: 5022 | I13: 5022 | J13: 4588 | K13: 5270 | L13: 4557 | M13: 5022 | N13: 4557 | O13: 4340 | P13: {=SUMPRODUCT((D$1:O$1<>"Margin")*(D$1:O$1<>"Salary_$600")*D13:O13)} -> 57133 | R13: 100% | S13: JSG | T13: ds_StaffingT02
A14: Mastek | B14: Wendy | C14: Staffing | D14: 10804 | E14: 10220 | F14: 12410 | G14: 10731 | H14: 11826 | I14: 11826 | J14: 13432 | K14: 0 | L14: 0 | M14: 0 | N14: 0 | O14: 0 | P14: {=SUMPRODUCT((D$1:O$1<>"Margin")*(D$1:O$1<>"Salary_$600")*D14:O14)} -> 81249 | R14: 100% | S14: Mastek | T14: ds_StaffingT02
A15: Matchpoint Solutions | B15: Wendy | C15: Staffing | D15: 6480 | E15: 12600 | F15: 15300 | G15: 13230 | H15: 14580 | I15: 14580 | J15: 5760 | K15: 0 | L15: 0 | M15: 0 | N15: 0 | O15: 0 | P15: {=SUMPRODUCT((D$1:O$1<>"Margin")*(D$1:O$1<>"Salary_$600")*D15:O15)} -> 82530 | R15: 100% | S15: MatchPoint Solutions | T15: ds_StaffingT02
A16: Maxonic | B16: Wendy | C16: Staffing | D16: 75611 | E16: 69485 | F16: 69376 | G16: 27481 | H16: 22062 | I16: 12312 | J16: 11248 | K16: 1216 | L16: 0 | M16: 0 | N16: 0 | O16: 0 | P16: {=SUMPRODUCT((D$1:O$1<>"Margin")*(D$1:O$1<>"Salary_$600")*D16:O16)} -> 288791 | R16: 100% | S16: Maxonic | T16: ds_StaffingT02
A17: Technology Partners | B17: Wendy | C17: Staffing | D17: 740 | E17: 700 | F17: 850 | G17: 735 | H17: 810 | I17: 810 | J17: 740 | K17: 850 | L17: 735 | M17: 810 | N17: 735 | O17: 700 | P17: {=SUMPRODUCT((D$1:O$1<>"Margin")*(D$1:O$1<>"Salary_$600")*D17:O17)} -> 9215 | R17: 100% | S17: Technology Partners | T17: ds_StaffingT02
A18: Vdart | B18: Wendy | C18: Staffing | D18: 8880 | E18: 8400 | F18: 10200 | G18: 8820 | H18: 9720 | I18: 10560 | J18: 0 | K18: 0 | L18: 0 | M18: 0 | N18: 0 | O18: 0 | P18: {=SUMPRODUCT((D$1:O$1<>"Margin")*(D$1:O$1<>"Salary_$600")*D18:O18)} -> 56580 | S18: Vdart | T18: ds_StaffingT02
A19: Sub-Total : Secured | D19: =SUM(D4:D18) -> 242004 | E19: =SUM(E4:E18) -> 233353 | F19: =SUM(F4:F18) -> 268360 | G19: =SUM(G4:G18) -> 199543 | H19: =SUM(H4:H18) -> 211681 | I19: =SUM(I4:I18) -> 202771 | J19: =SUM(J4:J18) -> 170669 | K19: =SUM(K4:K18) -> 162290 | ... P19: =SUM(P4:P18) -> 2199694
A20: Maxonic | B20: Pankaj/Wendy | C20: Staffing | D20: 12303 | E20: 11638 | F20: 14132 | G20: 24440 | H20: 13467 | I20: 26934 | J20: 12303 | K20: 28264 | L20: 12220 | M20: 13467 | N20: 12220 | O20: 0 | P20: {=SUMPRODUCT((D$1:O$1<>"Margin")*(D$1:O$1<>"Salary_$600")*D20:O20)} -> 181388 | S20: Maxonic | T20: ds_StaffingT03
A21: AZU Solutions | B21: Pankaj/Neeraj | C21: Staffing | D21: 0 | E21: 11200 | F21: 13600 | G21: 11760 | H21: 12960 | I21: 25920 | J21: 11840 | K21: 0 | L21: 11760 | M21: 12960 | N21: 0 | O21: 0 | P21: {=SUMPRODUCT((D$1:O$1<>"Margin")*(D$1:O$1<>"Salary_$600")*D21:O21)} -> 112000 | S21: AZU Solutions | T21: ds_StaffingT03
A22: MatchPoint Solutions | B22: Pankaj/Wendy | C22: Staffing | D22: 0 | E22: 10500 | F22: 12750 | G22: 11025 | H22: 12150 | I22: 12150 | J22: 11100 | K22: 12750 | L22: 11025 | M22: 12150 | N22: 0 | O22: 0 | P22: {=SUMPRODUCT((D$1:O$1<>"Margin")*(D$1:O$1<>"Salary_$600")*D22:O22)} -> 105600 | S22: MatchPoint Solutions | T22: ds_StaffingT03
A23: The Mice Group | B23: Pankaj/Wendy | C23: Staffing | D23: 0 | E23: 0 | F23: 0 | G23: 11760 | H23: 12960 | I23: 12960 | J23: 11840 | K23: 13600 | L23: 11760 | M23: 0 | N23: 0 | O23: 0 | P23: {=SUMPRODUCT((D$1:O$1<>"Margin")*(D$1:O$1<>"Salary_$600")*D23:O23)} -> 74880 | S23: The Mice Group | T23: ds_StaffingT03
A24: Technology Partners | B24: Shashank/Wendy | C24: Staffing | D24: 3088 | E24: 0 | F24: 850 | G24: 1470 | H24: 3240 | I24: 3240 | J24: 2960 | K24: 4250 | L24: 3675 | M24: 4860 | N24: 4410 | O24: 4900 | P24: {=SUMPRODUCT((D$1:O$1<>"Margin")*(D$1:O$1<>"Salary_$600")*D24:O24)} -> 36943 | S24: Technology Partners | T24: ds_StaffingT03
A25: VanderHouwen | B25: Shashank/Wendy | C25: Staffing | D25: 45297 | E25: 0 | F25: 13600 | G25: 23520 | H25: 51840 | I25: 51840 | J25: 47360 | K25: 68000 | L25: 58800 | M25: 77760 | N25: 70560 | O25: 78400 | P25: {=SUMPRODUCT((D$1:O$1<>"Margin")*(D$1:O$1<>"Salary_$600")*D25:O25)} -> 586977 | S25: VanderHouwen | T25: ds_StaffingT03
A26: JSG | B26: Shashank/Wendy | C26: Staffing | D26: 10710 | E26: 868 | F26: 2108 | G26: 1823 | H26: 3013 | I26: 3013 | J26: 2753 | K26: 3162 | L26: 2734 | M26: 3013 | N26: 2734 | O26: 2604 | P26: {=SUMPRODUCT((D$1:O$1<>"Margin")*(D$1:O$1<>"Salary_$600")*D26:O26)} -> 38535 | S26: JSG | T26: ds_StaffingT03
A27: Red Oak | B27: Shashank/Wendy | C27: Staffing | D27: 4257 | E27: 700 | F27: 1700 | G27: 2940 | H27: 3240 | I27: 4860 | J27: 5180 | K27: 6800 | L27: 5880 | M27: 7290 | N27: 6615 | O27: 2100 | P27: {=SUMPRODUCT((D$1:O$1<>"Margin")*(D$1:O$1<>"Salary_$600")*D27:O27)} -> 51562 | S27: Red Oak | T27: ds_StaffingT03
A28: Manpower Group | B28: Shashank/Wendy | C28: Staffing | D28: 22278 | E28: 0 | F28: 12750 | G28: 22050 | H28: 24300 | I28: 24300 | J28: 22200 | K28: 25500 | L28: 33075 | M28: 36450 | N28: 33075 | O28: 31500 | P28: {=SUMPRODUCT((D$1:O$1<>"Margin")*(D$1:O$1<>"Salary_$600")*D28:O28)} -> 287478 | S28: Manpower Group | T28: ds_StaffingT03
A29: Trans American (Mastek) | B29: Shashank/Wendy | C29: Staffing | D29: 0 | E29: 0 | F29: 0 | G29: 0 | H29: 0 | I29: 0 | J29: 0 | K29: 0 | L29: 0 | M29: 0 | N29: 0 | O29: 0 | P29: {=SUMPRODUCT((D$1:O$1<>"Margin")*(D$1:O$1<>"Salary_$600")*D29:O29)} -> 0 | S29: Mastek | T29: ds_StaffingT03
A30: Vdart | B30: Shashank/Wendy | C30: Staffing | D30: 0 | E30: 0 | F30: 0 | G30: 0 | H30: 0 | I30: 0 | J30: 0 | K30: 0 | L30: 0 | M30: 0 | N30: 0 | O30: 0 | P30: {=SUMPRODUCT((D$1:O$1<>"Margin")*(D$1:O$1<>"Salary_$600")*D30:O30)} -> 0 | S30: Vdart | T30: ds_StaffingT03
A31: New Logos | B31: Shashank/Wendy | C31: Staffing | D31: 16060 | E31: 0 | F31: 0 | G31: 0 | H31: 25272 | I31: 25272 | J31: 23088 | K31: 26520 | L31: 22932 | M31: 25272 | N31: 22932 | O31: 21840 | P31: {=SUMPRODUCT((D$1:O$1<>"Margin")*(D$1:O$1<>"Salary_$600")*D31:O31)} -> 209188 | S31: New Logos | T31: ds_StaffingT03
A32: Sub-Total : Projection (Wendy) | D32: =SUM(D20:D31) -> 113993 | E32: =SUM(E20:E31) -> 34906 | F32: =SUM(F20:F31) -> 71490 | G32: =SUM(G20:G31) -> 110788 | H32: =SUM(H20:H31) -> 162442 | I32: =SUM(I20:I31) -> 190489 | J32: =SUM(J20:J31) -> 150624 | K32: =SUM(K20:K31) -> 188846 | ... P32: =SUM(P20:P31) -> 1684551
A33: Total Staffing (Secured + Projection) | D33: =+D19+D32 -> 355997 | E33: =+E19+E32 -> 268259 | F33: =+F19+F32 -> 339850 | G33: =+G19+G32 -> 310331 | H33: =+H19+H32 -> 374123 | I33: =+I19+I32 -> 393260 | J33: =+J19+J32 -> 321293 | K33: =+K19+K32 -> 351136 | ... P33: =+P19+P32 -> 3884245

Sheet Sales by Customer- 2026
D1: Actual | E1: Salary_$600 | F1: Margin | G1: Actual | H1: Salary_$600 | I1: Margin | J1: Actual | K1: Salary_$600 | L1: Margin | M1: Actual | N1: Salary_$600 | O1: Margin | P1: Actual | Q1: Salary_$600 | R1: Margin | S1: Forecast | T1: Salary_$600 | U1: Margin | V1: Forecast | W1: Salary_$600 | X1: Margin | Y1: Forecast | Z1: Salary_$600 | AA1: Margin | AB1: Forecast | AC1: Salary_$600 | AD1: Margin | AE1: Forecast | AF1: Salary_$600 | AG1: Margin | AH1: Forecast | AI1: Salary_$600 | AJ1: Margin | AK1: Forecast | AL1: Salary_$600 | AM1: Margin
A2: Name | B2: POC | C2: Service | D2: 46023 | E2: 46023 | F2: 46023 | G2: 46054 | H2: 46054 | I2: 46054 | J2: 46082 | K2: 46082 | L2: 46082 | M2: 46113 | N2: 46113 | O2: 46113 | P2: 46143 | Q2: 46143 | R2: 46143 | S2: 46174 | T2: 46174 | U2: 46174 | V2: 46204 | W2: 46204 | X2: 46204 | Y2: 46235 | Z2: 46235 | AA2: 46235 | AB2: 46266 | AC2: 46266 | AD2: 46266 | AE2: 46296 | AF2: 46296 | AG2: 46296 | AH2: 46327 | AI2: 46327 | AJ2: 46327 | AK2: 46357 | AL2: 46357 | AM2: 46357 | AN2: Total Revenue | AO2: Total Margin | AP2: Comments | AQ2: Renewal Confidence | AR2: Group | AS2: Sub-Group | AU2: 2024 | AV2: 2025_Total | AW2: 2025_Q4
A3: Solutions and Staff Augmentation (Projects) - Track 1 | AR3: Track 1-Secured
A4: AI Forward | B4: Vijay | C4: Non Billable | D4: 0 | F4: =D4-E4 -> 0 | G4: 0 | I4: =G4-H4 -> 0 | J4: 0 | L4: =J4-K4 -> 0 | M4: 0 | N4: 3169 | O4: =M4-N4 -> -3169 | P4: 0 | Q4: 5610 | R4: =P4-Q4 -> -5610 | S4: 0 | T4: 12879 | U4: =S4-T4 -> -12879 | V4: 0 | W4: 12879 | X4: =V4-W4 -> -12879 | Y4: 0 | Z4: 12879 | AA4: =Y4-Z4 -> -12879 | AB4: 0 | AC4: 12879 | AD4: =AB4-AC4 -> -12879 | AE4: 0 | AF4: 12879 | AG4: =AE4-AF4 -> -12879 | AH4: 0 | AI4: 12879 | AJ4: =AH4-AI4 -> -12879 | AK4: 0 | AL4: 12879 | AM4: =AK4-AL4 -> -12879 | AN4: {=SUMPRODUCT((D$1:AK$1<>"Margin")*(D$1:AK$1<>"Salary_$600")*D4:AK4)} -> 0 | AO4: {=SUMPRODUCT((D$1:AM$1="Margin")*D4:AM4)} -> -98932 | AR4: AI Forward | AS4: DS10_Secured
A5: Bench | B5: Vijay | C5: Non Billable | E5: 25952 | F5: =D5-E5 -> -25952 | H5: 26606 | I5: =G5-H5 -> -26606 | K5: 22428 | L5: =J5-K5 -> -22428 | N5: 27663 | O5: =M5-N5 -> -27663 | Q5: 17634 | R5: =P5-Q5 -> -17634 | T5: 8174 | U5: =S5-T5 -> -8174 | W5: 8174 | X5: =V5-W5 -> -8174 | Z5: =6501+8174 -> 14675 | AA5: =Y5-Z5 -> -14675 | AC5: =6501+8174 -> 14675 | AD5: =AB5-AC5 -> -14675 | AF5: =6501+8174 -> 14675 | AG5: =AE5-AF5 -> -14675 | AI5: =6501+8174 -> 14675 | AJ5: =AH5-AI5 -> -14675 | AL5: =6501+8174 -> 14675 | AM5: =AK5-AL5 -> -14675 | AN5: {=SUMPRODUCT((D$1:AK$1<>"Margin")*(D$1:AK$1<>"Salary_$600")*D5:AK5)} -> 0 | AO5: {=SUMPRODUCT((D$1:AM$1="Margin")*D5:AM5)} -> -210006 | AR5: Bench | AS5: DS10_Secured
A6: Bench Deployed | B6: Vijay | C6: Non Billable | F6: =D6-E6 -> 0 | I6: =G6-H6 -> 0 | L6: =J6-K6 -> 0 | O6: =M6-N6 -> 0 | Q6: 2572 | R6: =P6-Q6 -> -2572 | T6: 2572 | U6: =S6-T6 -> -2572 | W6: 2572 | X6: =V6-W6 -> -2572 | Z6: 2572 | AA6: =Y6-Z6 -> -2572 | AC6: 2572 | AD6: =AB6-AC6 -> -2572 | AF6: 2572 | AG6: =AE6-AF6 -> -2572 | AI6: 2572 | AJ6: =AH6-AI6 -> -2572 | AL6: 2572 | AM6: =AK6-AL6 -> -2572 | AN6: {=SUMPRODUCT((D$1:AK$1<>"Margin")*(D$1:AK$1<>"Salary_$600")*D6:AK6)} -> 0 | AO6: {=SUMPRODUCT((D$1:AM$1="Margin")*D6:AM6)} -> -20576 | AR6: Bench Deployed | AS6: DS10_Secured
A7: MetaSys Payroll Portal-Truist | B7: Vijay | C7: Non Billable | F7: =D7-E7 -> 0 | I7: =G7-H7 -> 0 | K7: 4718 | L7: =J7-K7 -> -4718 | N7: 2544 | O7: =M7-N7 -> -2544 | Q7: 2544 | R7: =P7-Q7 -> -2544 | U7: =S7-T7 -> 0 | X7: =V7-W7 -> 0 | AA7: =Y7-Z7 -> 0 | AD7: =AB7-AC7 -> 0 | AG7: =AE7-AF7 -> 0 | AJ7: =AH7-AI7 -> 0 | AM7: =AK7-AL7 -> 0 | AN7: {=SUMPRODUCT((D$1:AK$1<>"Margin")*(D$1:AK$1<>"Salary_$600")*D7:AK7)} -> 0 | AO7: {=SUMPRODUCT((D$1:AM$1="Margin")*D7:AM7)} -> -9806 | AR7: MetaSys Payroll Portal-Truist | AS7: DS10_Secured
A8: MetaSys Staffing Reports Wendy | B8: Vijay | C8: Non Billable | D8: 0 | E8: 3169 | F8: =D8-E8 -> -3169 | G8: 0 | H8: 3169 | I8: =G8-H8 -> -3169 | J8: 0 | L8: =J8-K8 -> 0 | M8: 0 | O8: =M8-N8 -> 0 | P8: 0 | R8: =P8-Q8 -> 0 | S8: 0 | U8: =S8-T8 -> 0 | V8: 0 | X8: =V8-W8 -> 0 | Y8: 0 | AA8: =Y8-Z8 -> 0 | AB8: 0 | AD8: =AB8-AC8 -> 0 | AE8: 0 | AG8: =AE8-AF8 -> 0 | AH8: 0 | AJ8: =AH8-AI8 -> 0 | AK8: 0 | AM8: =AK8-AL8 -> 0 | AN8: {=SUMPRODUCT((D$1:AK$1<>"Margin")*(D$1:AK$1<>"Salary_$600")*D8:AK8)} -> 0 | AO8: {=SUMPRODUCT((D$1:AM$1="Margin")*D8:AM8)} -> -6338 | AR8: MetaSys Staffing Reports Wendy | AS8: DS10_Secured
A9: MetaSys, Marlow Content and Design | B9: Vijay | C9: Non Billable | D9: 0 | F9: =D9-E9 -> 0 | G9: 0 | I9: =G9-H9 -> 0 | J9: 0 | L9: =J9-K9 -> 0 | M9: 0 | O9: =M9-N9 -> 0 | P9: 0 | R9: =P9-Q9 -> 0 | S9: 0 | T9: 6501 | U9: =S9-T9 -> -6501 | V9: 0 | W9: 6501 | X9: =V9-W9 -> -6501 | Y9: 0 | AA9: =Y9-Z9 -> 0 | AB9: 0 | AD9: =AB9-AC9 -> 0 | AE9: 0 | AG9: =AE9-AF9 -> 0 | AH9: 0 | AJ9: =AH9-AI9 -> 0 | AK9: 0 | AM9: =AK9-AL9 -> 0 | AN9: {=SUMPRODUCT((D$1:AK$1<>"Margin")*(D$1:AK$1<>"Salary_$600")*D9:AK9)} -> 0 | AO9: {=SUMPRODUCT((D$1:AM$1="Margin")*D9:AM9)} -> -13002 | AR9: MetaSys, Marlow Content and Design | AS9: DS10_Secured
A10: Ovis Programming + MetaSys Websites | B10: Vijay | C10: Non Billable | D10: 0 | F10: =D10-E10 -> 0 | G10: 0 | I10: =G10-H10 -> 0 | J10: 0 | L10: =J10-K10 -> 0 | M10: 0 | O10: =M10-N10 -> 0 | P10: 0 | Q10: 7445 | R10: =P10-Q10 -> -7445 | S10: 0 | T10: 8786 | U10: =S10-T10 -> -8786 | V10: 0 | W10: 8786 | X10: =V10-W10 -> -8786 | Y10: 0 | Z10: 8786 | AA10: =Y10-Z10 -> -8786 | AB10: 0 | AC10: 8786 | AD10: =AB10-AC10 -> -8786 | AE10: 0 | AF10: 8786 | AG10: =AE10-AF10 -> -8786 | AH10: 0 | AI10: 8786 | AJ10: =AH10-AI10 -> -8786 | AK10: 0 | AL10: 8786 | AM10: =AK10-AL10 -> -8786 | AN10: {=SUMPRODUCT((D$1:AK$1<>"Margin")*(D$1:AK$1<>"Salary_$600")*D10:AK10)} -> 0 | AO10: {=SUMPRODUCT((D$1:AM$1="Margin")*D10:AM10)} -> -68947 | AR10: Ovis Programming + MetaSys Websites | AS10: DS10_Secured
A11: Ovis- Creative Support | B11: Vijay | C11: Non Billable | N11: 1619 | O11: =M11-N11 -> -1619 | AN11: {=SUMPRODUCT((D$1:AK$1<>"Margin")*(D$1:AK$1<>"Salary_$600")*D11:AK11)} -> 0 | AO11: {=SUMPRODUCT((D$1:AM$1="Margin")*D11:AM11)} -> -1619 | AR11: Ovis- Creative Support | AS11: DS10_Secured
A12: Sales & Marketing (Nvish & MetaSys) | B12: Vijay | C12: Non Billable | D12: 0 | E12: 11387 | F12: =D12-E12 -> -11387 | G12: 0 | H12: 10945 | I12: =G12-H12 -> -10945 | J12: 0 | K12: 10945 | L12: =J12-K12 -> -10945 | M12: 0 | N12: 9115 | O12: =M12-N12 -> -9115 | P12: 0 | Q12: 9115 | R12: =P12-Q12 -> -9115 | S12: 0 | T12: 9115 | U12: =S12-T12 -> -9115 | V12: 0 | W12: 9115 | X12: =V12-W12 -> -9115 | Y12: 0 | Z12: 9115 | AA12: =Y12-Z12 -> -9115 | AB12: 0 | AC12: 9115 | AD12: =AB12-AC12 -> -9115 | AE12: 0 | AF12: 9115 | AG12: =AE12-AF12 -> -9115 | AH12: 0 | AI12: 9115 | AJ12: =AH12-AI12 -> -9115 | AK12: 0 | AL12: 9115 | AM12: =AK12-AL12 -> -9115 | AN12: {=SUMPRODUCT((D$1:AK$1<>"Margin")*(D$1:AK$1<>"Salary_$600")*D12:AK12)} -> 0 | AO12: {=SUMPRODUCT((D$1:AM$1="Margin")*D12:AM12)} -> -115312 | AR12: Sales & Marketing (Nvish & MetaSys) | AS12: DS10_Secured
A13: Automation Anywhere Web Dev | B13: Neeraj | C13: Staff Aug | D13: 30000 | E13: 30276 | F13: =D13-E13 -> -276 | G13: 30000 | H13: ='Salary Projections 2026'!$B$2 -> 26522 | I13: =G13-H13 -> 3478 | J13: 30000 | K13: ='Salary Projections 2026'!$B$2 -> 26522 | L13: =J13-K13 -> 3478 | M13: 30000 | N13: =VLOOKUP($A13,'Salary Projections 2026'!$A:$D,3,FALSE) -> 26522 | O13: =M13-N13 -> 3478 | P13: 30000 | Q13: =VLOOKUP($A13,'Salary Projections 2026'!$A:$D,3,FALSE) -> 26522 | R13: =P13-Q13 -> 3478 | S13: 30000 | T13: =VLOOKUP($A13,'Salary Projections 2026'!$A:$D,3,FALSE) -> 26522 | U13: =S13-T13 -> 3478 | V13: 30000 | W13: =VLOOKUP($A13,'Salary Projections 2026'!$A:$D,3,FALSE) -> 26522 | X13: =V13-W13 -> 3478 | Y13: 33350 | Z13: =VLOOKUP($A13,'Salary Projections 2026'!$A:$D,3,FALSE) -> 26522 | AA13: =Y13-Z13 -> 6828 | AB13: 33350 | AC13: =VLOOKUP($A13,'Salary Projections 2026'!$A:$D,3,FALSE) -> 26522 | AD13: =AB13-AC13 -> 6828 | AE13: 33350 | AF13: =VLOOKUP($A13,'Salary Projections 2026'!$A:$D,4,FALSE) -> 26522 | AG13: =AE13-AF13 -> 6828 | AH13: 33350 | AI13: =VLOOKUP($A13,'Salary Projections 2026'!$A:$D,4,FALSE) -> 26522 | AJ13: =AH13-AI13 -> 6828 | AK13: 33350 | AL13: =VLOOKUP($A13,'Salary Projections 2026'!$A:$D,4,FALSE) -> 26522 | AM13: =AK13-AL13 -> 6828 | AN13: {=SUMPRODUCT((D$1:AK$1<>"Margin")*(D$1:AK$1<>"Salary_$600")*D13:AK13)} -> 376750 | AO13: {=SUMPRODUCT((D$1:AM$1="Margin")*D13:AM13)} -> 54732 | AP13: SOW valid until Jan 2026. On SOW renewal, the client has reduced the monthly billing. Feb - July 2026 - $30K per month | AQ13: 100% | AR13: Automation Anywhere | AS13: DS10_Secured | AU13: 546884 | AV13: 411812 | AW13: 98766
A14: AIS Solutions | B14: Vijay | C14: Staff Aug | D14: 0 | E14: 0 | F14: 0 | G14: 0 | H14: 1341 | I14: =G14-H14 -> -1341 | J14: 5000 | K14: 1341 | L14: =J14-K14 -> 3659 | M14: 5000 | N14: 1341 | O14: =M14-N14 -> 3659 | P14: 5000 | Q14: =1341/2 -> 670.5 | R14: =P14-Q14 -> 4329.5 | S14: 0 | T14: 0 | U14: 0 | V14: 0 | W14: 0 | X14: 0 | Y14: 0 | Z14: 0 | AA14: 0 | AB14: 0 | AC14: 0 | AD14: 0 | AE14: 0 | AF14: 0 | AG14: 0 | AH14: 0 | AI14: 0 | AJ14: 0 | AK14: 0 | AL14: 0 | AM14: 0 | AN14: {=SUMPRODUCT((D$1:AK$1<>"Margin")*(D$1:AK$1<>"Salary_$600")*D14:AK14)} -> 15000 | AO14: {=SUMPRODUCT((D$1:AM$1="Margin")*D14:AM14)} -> 10306.5 | AQ14: 0% | AR14: AIS Solutions | AS14: DS10_Secured | AU14: 0 | AV14: 0 | AW14: 0
A15: Aldevron - Address Cookie Compliance Issue | B15: Neeraj | C15: Project | D15: 1200 | E15: 600 | F15: =D15-E15 -> 600 | G15: 0 | J15: 0 | M15: 0 | P15: 0 | S15: 0 | V15: 0 | Y15: 0 | AB15: 0 | AE15: 0 | AH15: 0 | AK15: 0 | AN15: {=SUMPRODUCT((D$1:AK$1<>"Margin")*(D$1:AK$1<>"Salary_$600")*D15:AK15)} -> 1200 | AO15: {=SUMPRODUCT((D$1:AM$1="Margin")*D15:AM15)} -> 600 | AQ15: 100% | AR15: Aldevron | AS15: DS10_Secured
A16: Aldevron - Website Support & Maintenance | B16: Neeraj | C16: Staff Aug | D16: 0 | G16: 8150 | H16: 3940 | I16: =G16-H16 -> 4210 | J16: 8150 | K16: 3940 | L16: =J16-K16 -> 4210 | M16: 8150 | N16: 3940 | O16: =M16-N16 -> 4210 | P16: 8150 | Q16: 3940 | R16: =P16-Q16 -> 4210 | S16: 8150 | T16: 3940 | U16: =S16-T16 -> 4210 | V16: 8150 | W16: 3940 | X16: =V16-W16 -> 4210 | Y16: 8150 | Z16: 3940 | AA16: =Y16-Z16 -> 4210 | AB16: 8150 | AC16: 3940 | AD16: =AB16-AC16 -> 4210 | AE16: 8150 | AF16: 3940 | AG16: =AE16-AF16 -> 4210 | AH16: 8150 | AI16: 3940 | AJ16: =AH16-AI16 -> 4210 | AK16: 8150 | AL16: 3940 | AM16: =AK16-AL16 -> 4210 | AN16: {=SUMPRODUCT((D$1:AK$1<>"Margin")*(D$1:AK$1<>"Salary_$600")*D16:AK16)} -> 89650 | AO16: {=SUMPRODUCT((D$1:AM$1="Margin")*D16:AM16)} -> 46310 | AQ16: 100% | AR16: Aldevron | AS16: DS10_Secured
A17: Aldevron - SEO Strategy & Optimization | B17: Neeraj | C17: Staff Aug | D17: 0 | E17: 0 | F17: 0 | G17: 0 | H17: 0 | I17: 0 | J17: 0 | K17: 0 | L17: 0 | M17: 0 | N17: 0 | O17: 0 | P17: 0 | Q17: 0 | R17: 0 | S17: 2500 | T17: 1500 | U17: =S17-T17 -> 1000 | V17: 2500 | W17: 1500 | X17: =V17-W17 -> 1000 | Y17: 2500 | Z17: 1500 | AA17: =Y17-Z17 -> 1000 | AB17: 2500 | AC17: 1500 | AD17: =AB17-AC17 -> 1000 | AE17: 2500 | AF17: 1500 | AG17: =AE17-AF17 -> 1000 | AH17: 2500 | AI17: 1500 | AJ17: =AH17-AI17 -> 1000 | AK17: 2500 | AL17: 1500 | AM17: =AK17-AL17 -> 1000 | AN17: {=SUMPRODUCT((D$1:AK$1<>"Margin")*(D$1:AK$1<>"Salary_$600")*D17:AK17)} -> 17500 | AO17: {=SUMPRODUCT((D$1:AM$1="Margin")*D17:AM17)} -> 7000 | AR17: Aldevron | AS17: DS10_Secured
A18: CheckPoint Desktop publishing of translated assets | B18: Neeraj | C18: Staff Aug | D18: 5000 | E18: =VLOOKUP($A18,'Salary Projections 2026'!$A:$D,2,FALSE) -> 849 | F18: =D18-E18 -> 4151 | G18: 0 | H18: =VLOOKUP($A18,'Salary Projections 2026'!$A:$D,2,FALSE) -> 849 | I18: =G18-H18 -> -849 | J18: 702 | K18: =VLOOKUP($A18,'Salary Projections 2026'!$A:$D,2,FALSE) -> 849 | L18: =J18-K18 -> -147 | M18: 0 | N18: 0 | O18: 0 | P18: 0 | Q18: 0 | R18: 0 | S18: 0 | T18: 0 | U18: 0 | V18: 0 | W18: 0 | X18: 0 | Y18: 0 | Z18: 0 | AA18: 0 | AB18: 0 | AC18: 0 | AD18: 0 | AE18: 0 | AF18: 0 | AG18: 0 | AH18: 0 | AI18: 0 | AJ18: 0 | AK18: 0 | AL18: 0 | AM18: 0 | AN18: {=SUMPRODUCT((D$1:AK$1<>"Margin")*(D$1:AK$1<>"Salary_$600")*D18:AK18)} -> 5702 | AO18: {=SUMPRODUCT((D$1:AM$1="Margin")*D18:AM18)} -> 3155 | AP18: SOW valid Feb 2026. For the last 2 years client is continuously renewing for 5 months. | AQ18: 0% | AR18: CheckPoint | AS18: DS10_Secured | AU18: 30190 | AV18: 24990 | AW18: 5000
A19: Church's Chicken & IT Support | B19: Neeraj | C19: Project | D19: 0 | E19: =VLOOKUP($A19,'Salary Projections 2026'!$A:$D,2,FALSE) -> 201 | F19: =D19-E19 -> -201 | G19: 0 | H19: =VLOOKUP($A19,'Salary Projections 2026'!$A:$D,2,FALSE) -> 201 | I19: =G19-H19 -> -201 | J19: 7500 | K19: =VLOOKUP($A19,'Salary Projections 2026'!$A:$D,2,FALSE) -> 201 | L19: =J19-K19 -> 7299 | M19: 0 | N19: =VLOOKUP($A19,'Salary Projections 2026'!$A:$D,3,FALSE) -> 201 | O19: =M19-N19 -> -201 | P19: 0 | Q19: =VLOOKUP($A19,'Salary Projections 2026'!$A:$D,3,FALSE) -> 201 | R19: =P19-Q19 -> -201 | S19: 0 | T19: =VLOOKUP($A19,'Salary Projections 2026'!$A:$D,3,FALSE) -> 201 | U19: =S19-T19 -> -201 | W19: =VLOOKUP($A19,'Salary Projections 2026'!$A:$D,3,FALSE) -> 201 | X19: =V19-W19 -> -201 | Y19: 0 | Z19: =VLOOKUP($A19,'Salary Projections 2026'!$A:$D,3,FALSE) -> 201 | AA19: =Y19-Z19 -> -201 | AB19: 0 | AC19: =VLOOKUP($A19,'Salary Projections 2026'!$A:$D,3,FALSE) -> 201 | AD19: =AB19-AC19 -> -201 | AE19: 0 | AF19: =VLOOKUP($A19,'Salary Projections 2026'!$A:$D,4,FALSE) -> 201 | AG19: =AE19-AF19 -> -201 | AH19: 0 | AI19: =VLOOKUP($A19,'Salary Projections 2026'!$A:$D,4,FALSE) -> 201 | AJ19: =AH19-AI19 -> -201 | AK19: 0 | AL19: =VLOOKUP($A19,'Salary Projections 2026'!$A:$D,4,FALSE) -> 201 | AM19: =AK19-AL19 -> -201 | AN19: {=SUMPRODUCT((D$1:AK$1<>"Margin")*(D$1:AK$1<>"Salary_$600")*D19:AK19)} -> 7500 | AO19: {=SUMPRODUCT((D$1:AM$1="Margin")*D19:AM19)} -> 5088 | AP19: SOW valid until Dec 31, 2027 | AQ19: 100% | AR19: Churchs-Chicken | AS19: DS10_Secured | AU19: 7500 | AV19: 75000 | AW19: 0
A20: Databricks Ongoing Support | B20: Neeraj | C20: Staff Aug | D20: 60499 | E20: 34000 | F20: =D20-E20 -> 26499 | G20: =57475+8825 -> 66300 | H20: =VLOOKUP($A20,'Salary Projections 2026'!$A:$D,2,FALSE) -> 38488 | I20: =G20-H20 -> 27812 | J20: =57475+8825 -> 66300 | K20: =VLOOKUP($A20,'Salary Projections 2026'!$A:$D,2,FALSE) -> 38488 | L20: =J20-K20 -> 27812 | M20: 67885 | N20: 37870 | O20: =M20-N20 -> 30015 | P20: =57475+8825+3875 -> 70175 | Q20: =VLOOKUP($A20,'Salary Projections 2026'!$A:$D,3,FALSE)+1248 -> 39736 | R20: =P20-Q20 -> 30439 | S20: =57475+8825+3875 -> 70175 | T20: =VLOOKUP($A20,'Salary Projections 2026'!$A:$D,3,FALSE)+1248 -> 39736 | U20: =S20-T20 -> 30439 | V20: =57475+8825 -> 66300 | W20: =VLOOKUP($A20,'Salary Projections 2026'!$A:$D,3,FALSE) -> 38488 | X20: =V20-W20 -> 27812 | Y20: =57475+8825 -> 66300 | Z20: =VLOOKUP($A20,'Salary Projections 2026'!$A:$D,3,FALSE) -> 38488 | AA20: =Y20-Z20 -> 27812 | AB20: =57475+8825 -> 66300 | AC20: =VLOOKUP($A20,'Salary Projections 2026'!$A:$D,3,FALSE) -> 38488 | AD20: =AB20-AC20 -> 27812 | AE20: =57475+8825 -> 66300 | AF20: =VLOOKUP($A20,'Salary Projections 2026'!$A:$D,4,FALSE) -> 38488 | AG20: =AE20-AF20 -> 27812 | AH20: =57475+8825 -> 66300 | AI20: =VLOOKUP($A20,'Salary Projections 2026'!$A:$D,4,FALSE) -> 38488 | AJ20: =AH20-AI20 -> 27812 | AK20: =57475+8825 -> 66300 | AL20: =VLOOKUP($A20,'Salary Projections 2026'!$A:$D,4,FALSE) -> 38488 | AM20: =AK20-AL20 -> 27812 | AN20: {=SUMPRODUCT((D$1:AK$1<>"Margin")*(D$1:AK$1<>"Salary_$600")*D20:AK20)} -> 799134 | AO20: {=SUMPRODUCT((D$1:AM$1="Margin")*D20:AM20)} -> 339888 | AP20: Current SOW valid until Sep 30, 2026. Amendment approved for 2 additional resoruces with addiitonal billing $8,825/month (Starting Jan 2026) | AQ20: 100% | AR20: Databricks | AS20: DS10_Secured | AU20: 1099676 | AV20: 1817631 | AW20: 481904
A21: Databricks Planning Project | B21: Neeraj | C21: Staff Aug | D21: 5000 | E21: =VLOOKUP($A21,'Salary Projections 2026'!$A:$D,2,FALSE) -> 3517 | F21: =D21-E21 -> 1483 | G21: 5000 | H21: =VLOOKUP($A21,'Salary Projections 2026'!$A:$D,2,FALSE) -> 3517 | I21: =G21-H21 -> 1483 | J21: 5000 | K21: =VLOOKUP($A21,'Salary Projections 2026'!$A:$D,2,FALSE) -> 3517 | L21: =J21-K21 -> 1483 | M21: 5000 | N21: =VLOOKUP($A21,'Salary Projections 2026'!$A:$D,3,FALSE) -> 3517 | O21: =M21-N21 -> 1483 | P21: 5000 | Q21: =VLOOKUP($A21,'Salary Projections 2026'!$A:$D,3,FALSE) -> 3517 | R21: =P21-Q21 -> 1483 | S21: 5000 | T21: =VLOOKUP($A21,'Salary Projections 2026'!$A:$D,3,FALSE) -> 3517 | U21: =S21-T21 -> 1483 | V21: 5000 | W21: =VLOOKUP($A21,'Salary Projections 2026'!$A:$D,3,FALSE) -> 3517 | X21: =V21-W21 -> 1483 | Y21: 5000 | Z21: =VLOOKUP($A21,'Salary Projections 2026'!$A:$D,3,FALSE) -> 3517 | AA21: =Y21-Z21 -> 1483 | AB21: 5000 | AC21: =VLOOKUP($A21,'Salary Projections 2026'!$A:$D,3,FALSE) -> 3517 | AD21: =AB21-AC21 -> 1483 | AE21: 5000 | AF21: =VLOOKUP($A21,'Salary Projections 2026'!$A:$D,4,FALSE) -> 3517 | AG21: =AE21-AF21 -> 1483 | AH21: 5000 | AI21: =VLOOKUP($A21,'Salary Projections 2026'!$A:$D,4,FALSE) -> 3517 | AJ21: =AH21-AI21 -> 1483 | AK21: 5000 | AL21: =VLOOKUP($A21,'Salary Projections 2026'!$A:$D,4,FALSE) -> 3517 | AM21: =AK21-AL21 -> 1483 | AN21: {=SUMPRODUCT((D$1:AK$1<>"Margin")*(D$1:AK$1<>"Salary_$600")*D21:AK21)} -> 60000 | AO21: {=SUMPRODUCT((D$1:AM$1="Margin")*D21:AM21)} -> 17796 | AP21: SOW valid until April 30, 2026. | AQ21: 100% | AR21: Databricks | AS21: DS10_Secured
A22: Databricks Program Manager and Marketo | B22: Neeraj | C22: Staff Aug | D22: 81850 | E22: =VLOOKUP($A22,'Salary Projections 2026'!$A:$D,2,FALSE) -> 55460 | F22: =D22-E22 -> 26390 | G22: 81850 | H22: =VLOOKUP($A22,'Salary Projections 2026'!$A:$D,2,FALSE) -> 55460 | I22: =G22-H22 -> 26390 | J22: 81850 | K22: =VLOOKUP($A22,'Salary Projections 2026'!$A:$D,2,FALSE) -> 55460 | L22: =J22-K22 -> 26390 | M22: 81850 | N22: =VLOOKUP($A22,'Salary Projections 2026'!$A:$D,3,FALSE) -> 53358 | O22: =M22-N22 -> 28492 | P22: 78000 | Q22: =18650+39245 -> 57895 | R22: =P22-Q22 -> 20105 | S22: 78000 | T22: =80*56+39245+12716 -> 56441 | U22: =S22-T22 -> 21559 | V22: 78000 | W22: =VLOOKUP($A22,'Salary Projections 2026'!$A:$D,3,FALSE) -> 53358 | X22: =V22-W22 -> 24642 | Y22: 78000 | Z22: =VLOOKUP($A22,'Salary Projections 2026'!$A:$D,3,FALSE) -> 53358 | AA22: =Y22-Z22 -> 24642 | AB22: 78000 | AC22: =VLOOKUP($A22,'Salary Projections 2026'!$A:$D,3,FALSE) -> 53358 | AD22: =AB22-AC22 -> 24642 | AE22: 93000 | AF22: =VLOOKUP($A22,'Salary Projections 2026'!$A:$D,3,FALSE) -> 53358 | AG22: =AE22-AF22 -> 39642 | AH22: 93000 | AI22: =VLOOKUP($A22,'Salary Projections 2026'!$A:$D,4,FALSE) -> 65358 | AJ22: =AH22-AI22 -> 27642 | AK22: 93000 | AL22: =VLOOKUP($A22,'Salary Projections 2026'!$A:$D,4,FALSE) -> 65358 | AM22: =AK22-AL22 -> 27642 | AN22: {=SUMPRODUCT((D$1:AK$1<>"Margin")*(D$1:AK$1<>"Salary_$600")*D22:AK22)} -> 996400 | AO22: {=SUMPRODUCT((D$1:AM$1="Margin")*D22:AM22)} -> 318178 | AP22: SOW valid until April 30, 2026. | AQ22: 100% | AR22: Databricks | AS22: DS10_Secured
A23: Databricks SEO Project Management | B23: Neeraj | C23: Staff Aug | D23: 4500 | E23: =VLOOKUP($A23,'Salary Projections 2026'!$A:$D,2,FALSE) -> 3568 | F23: =D23-E23 -> 932 | G23: 4500 | H23: =VLOOKUP($A23,'Salary Projections 2026'!$A:$D,2,FALSE) -> 3568 | I23: =G23-H23 -> 932 | J23: 4500 | K23: =VLOOKUP($A23,'Salary Projections 2026'!$A:$D,2,FALSE) -> 3568 | L23: =J23-K23 -> 932 | M23: 4500 | N23: =VLOOKUP($A23,'Salary Projections 2026'!$A:$D,3,FALSE) -> 3568 | O23: =M23-N23 -> 932 | P23: 4500 | Q23: =VLOOKUP($A23,'Salary Projections 2026'!$A:$D,3,FALSE) -> 3568 | R23: =P23-Q23 -> 932 | S23: 4500 | T23: =VLOOKUP($A23,'Salary Projections 2026'!$A:$D,3,FALSE) -> 3568 | U23: =S23-T23 -> 932 | V23: 0 | W23: 0 | X23: 0 | Y23: 4500 | Z23: =VLOOKUP($A23,'Salary Projections 2026'!$A:$D,3,FALSE) -> 3568 | AA23: =Y23-Z23 -> 932 | AB23: 4500 | AC23: =VLOOKUP($A23,'Salary Projections 2026'!$A:$D,3,FALSE) -> 3568 | AD23: =AB23-AC23 -> 932 | AE23: 4500 | AF23: =VLOOKUP($A23,'Salary Projections 2026'!$A:$D,4,FALSE) -> 3568 | AG23: =AE23-AF23 -> 932 | AH23: 4500 | AI23: =VLOOKUP($A23,'Salary Projections 2026'!$A:$D,4,FALSE) -> 3568 | AJ23: =AH23-AI23 -> 932 | AK23: 4500 | AL23: =VLOOKUP($A23,'Salary Projections 2026'!$A:$D,4,FALSE) -> 3568 | AM23: =AK23-AL23 -> 932 | AN23: {=SUMPRODUCT((D$1:AK$1<>"Margin")*(D$1:AK$1<>"Salary_$600")*D23:AK23)} -> 49500 | AO23: {=SUMPRODUCT((D$1:AM$1="Margin")*D23:AM23)} -> 10252 | AP23: SOW valid until April 30, 2026. | AQ23: 100% | AR23: Databricks | AS23: DS10_Secured
A24: Databricks Martech Platform Operations Administrator | B24: Neeraj | C24: Staff Aug | D24: 13500 | E24: =VLOOKUP($A24,'Salary Projections 2026'!$A:$D,2,FALSE) -> 7419 | F24: =D24-E24 -> 6081 | G24: 13500 | H24: =VLOOKUP($A24,'Salary Projections 2026'!$A:$D,2,FALSE) -> 7419 | I24: =G24-H24 -> 6081 | J24: =13500 -> 13500 | K24: =VLOOKUP($A24,'Salary Projections 2026'!$A:$D,2,FALSE) -> 7419 | L24: =J24-K24 -> 6081 | M24: 9000 | N24: 4689 | O24: =M24-N24 -> 4311 | P24: =3*4500 -> 13500 | Q24: =VLOOKUP($A24,'Salary Projections 2026'!$A:$D,3,FALSE) -> 7511 | R24: =P24-Q24 -> 5989 | S24: =3*4500 -> 13500 | T24: =VLOOKUP($A24,'Salary Projections 2026'!$A:$D,3,FALSE) -> 7511 | U24: =S24-T24 -> 5989 | V24: =3*4500 -> 13500 | W24: =VLOOKUP($A24,'Salary Projections 2026'!$A:$D,3,FALSE) -> 7511 | X24: =V24-W24 -> 5989 | Y24: =3*4500 -> 13500 | Z24: =VLOOKUP($A24,'Salary Projections 2026'!$A:$D,3,FALSE) -> 7511 | AA24: =Y24-Z24 -> 5989 | AB24: =3*4500 -> 13500 | AC24: =VLOOKUP($A24,'Salary Projections 2026'!$A:$D,3,FALSE) -> 7511 | AD24: =AB24-AC24 -> 5989 | AE24: =3*4500 -> 13500 | AF24: =VLOOKUP($A24,'Salary Projections 2026'!$A:$D,4,FALSE) -> 7511 | AG24: =AE24-AF24 -> 5989 | AH24: =3*4500 -> 13500 | AI24: =VLOOKUP($A24,'Salary Projections 2026'!$A:$D,4,FALSE) -> 7511 | AJ24: =AH24-AI24 -> 5989 | AK24: =3*4500 -> 13500 | AL24: =VLOOKUP($A24,'Salary Projections 2026'!$A:$D,4,FALSE) -> 7511 | AM24: =AK24-AL24 -> 5989 | AN24: {=SUMPRODUCT((D$1:AK$1<>"Margin")*(D$1:AK$1<>"Salary_$600")*D24:AK24)} -> 157500 | AO24: {=SUMPRODUCT((D$1:AM$1="Margin")*D24:AM24)} -> 70466 | AP24: SOW valid until April 30, 2026. | AQ24: 100% | AR24: Databricks | AS24: DS10_Secured
A25: Doppel - Website Support & Maintenance | B25: Neeraj | C25: Staff Aug | D25: 0 | E25: 0 | F25: 0 | G25: 0 | H25: 0 | I25: 0 | J25: 0 | K25: 0 | L25: 0 | M25: 0 | N25: 0 | O25: 0 | P25: 0 | Q25: 0 | R25: 0 | S25: 0 | T25: 0 | U25: 0 | V25: 0 | W25: 0 | X25: 0 | Y25: 0 | Z25: 0 | AA25: 0 | AB25: 0 | AC25: 0 | AD25: 0 | AE25: 0 | AF25: 0 | AG25: 0 | AH25: 0 | AI25: 0 | AJ25: 0 | AK25: 0 | AL25: 0 | AM25: 0 | AN25: {=SUMPRODUCT((D$1:AK$1<>"Margin")*(D$1:AK$1<>"Salary_$600")*D25:AK25)} -> 0 | AO25: {=SUMPRODUCT((D$1:AM$1="Margin")*D25:AM25)} -> 0 | AQ25: 25% | AR25: Doppel | AS25: DS10_Secured | AU25: 0 | AV25: 0 | AW25: 0
A26: EGIA Development Support | B26: Neeraj | C26: Staff Aug | D26: 39000 | E26: =VLOOKUP($A26,'Salary Projections 2026'!$A:$D,2,FALSE) -> 17108 | F26: =D26-E26 -> 21892 | G26: 39000 | H26: =VLOOKUP($A26,'Salary Projections 2026'!$A:$D,2,FALSE) -> 17108 | I26: =G26-H26 -> 21892 | J26: 39000 | K26: =VLOOKUP($A26,'Salary Projections 2026'!$A:$D,2,FALSE) -> 17108 | L26: =J26-K26 -> 21892 | M26: 39000 | N26: =VLOOKUP($A26,'Salary Projections 2026'!$A:$D,3,FALSE) -> 17108 | O26: =M26-N26 -> 21892 | P26: 39000 | Q26: =VLOOKUP($A26,'Salary Projections 2026'!$A:$D,3,FALSE) -> 17108 | R26: =P26-Q26 -> 21892 | S26: 39000 | T26: =VLOOKUP($A26,'Salary Projections 2026'!$A:$D,3,FALSE) -> 17108 | U26: =S26-T26 -> 21892 | V26: 39000 | W26: =VLOOKUP($A26,'Salary Projections 2026'!$A:$D,3,FALSE) -> 17108 | X26: =V26-W26 -> 21892 | Y26: 39000 | Z26: =VLOOKUP($A26,'Salary Projections 2026'!$A:$D,3,FALSE) -> 17108 | AA26: =Y26-Z26 -> 21892 | AB26: 39000 | AC26: =VLOOKUP($A26,'Salary Projections 2026'!$A:$D,3,FALSE) -> 17108 | AD26: =AB26-AC26 -> 21892 | AE26: 39000 | AF26: =VLOOKUP($A26,'Salary Projections 2026'!$A:$D,4,FALSE) -> 17108 | AG26: =AE26-AF26 -> 21892 | AH26: 39000 | AI26: =VLOOKUP($A26,'Salary Projections 2026'!$A:$D,4,FALSE) -> 17108 | AJ26: =AH26-AI26 -> 21892 | AK26: 39000 | AL26: =VLOOKUP($A26,'Salary Projections 2026'!$A:$D,4,FALSE) -> 17108 | AM26: =AK26-AL26 -> 21892 | AN26: {=SUMPRODUCT((D$1:AK$1<>"Margin")*(D$1:AK$1<>"Salary_$600")*D26:AK26)} -> 468000 | AO26: {=SUMPRODUCT((D$1:AM$1="Margin")*D26:AM26)} -> 262704 | AP26: Open Ended SOW | AQ26: 100% | AR26: EGIA | AS26: DS10_Secured | AU26: 604000 | AV26: 468000 | AW26: 117000
A27: Hitachi Asia | B27: Vijay | C27: Project | D27: 0 | E27: =VLOOKUP($A27,'Salary Projections 2026'!$A:$D,2,FALSE) -> 22701.667 | F27: =D27-E27 -> -22701.667 | G27: 0 | H27: =VLOOKUP($A27,'Salary Projections 2026'!$A:$D,2,FALSE) -> 22701.667 | I27: =G27-H27 -> -22701.667 | J27: 116000 | K27: =VLOOKUP($A27,'Salary Projections 2026'!$A:$D,2,FALSE) -> 22701.667 | L27: =J27-K27 -> 93298.333 | M27: 0 | N27: 4566 | O27: =M27-N27 -> -4566 | P27: 0 | Q27: 4566 | R27: =P27-Q27 -> -4566 | S27: 0 | T27: 4566 | U27: =S27-T27 -> -4566 | V27: 0 | W27: 4566 | X27: =V27-W27 -> -4566 | Y27: 0 | Z27: 4566 | AA27: =Y27-Z27 -> -4566 | AB27: 131770 | AC27: 4566 | AD27: =AB27-AC27 -> 127204 | AE27: 0 | AF27: 4566 | AG27: =AE27-AF27 -> -4566 | AH27: 0 | AI27: 4566 | AJ27: =AH27-AI27 -> -4566 | AK27: 0 | AL27: 4566 | AM27: =AK27-AL27 -> -4566 | AN27: {=SUMPRODUCT((D$1:AK$1<>"Margin")*(D$1:AK$1<>"Salary_$600")*D27:AK27)} -> 247770 | AO27: {=SUMPRODUCT((D$1:AM$1="Margin")*D27:AM27)} -> 138571 | AP27: Revenue until March is actual Revenue April - Dec are projections based on proposals under discussion | AQ27: 75% | AR27: Hitachi Asia | AS27: DS10_Secured | AU27: 543456 | AV27: 546277 | AW27: 155360
A28: HEA Website Updates | B28: Vijay | C28: Project | D28: 0 | E28: 0 | F28: 0 | G28: 0 | H28: 0 | I28: 0 | J28: 0 | K28: 0 | L28: 0 | M28: 0 | N28: 0 | O28: 0 | P28: 2770 | Q28: 0 | R28: =P28-Q28 -> 2770 | S28: 0 | T28: 0 | U28: 0 | V28: 0 | W28: 0 | X28: 0 | Y28: 0 | Z28: 0 | AA28: 0 | AB28: 0 | AC28: 0 | AD28: 0 | AE28: 0 | AF28: 0 | AG28: 0 | AH28: 0 | AI28: 0 | AJ28: 0 | AK28: 0 | AL28: 0 | AM28: 0 | AN28: {=SUMPRODUCT((D$1:AK$1<>"Margin")*(D$1:AK$1<>"Salary_$600")*D28:AK28)} -> 2770 | AO28: {=SUMPRODUCT((D$1:AM$1="Margin")*D28:AM28)} -> 2770 | AQ28: 100% | AR28: Hitachi Asia | AS28: DS10_Secured
A29: HAL Creative Support | B29: Neeraj | C29: Staff Aug | D29: 0 | E29: =VLOOKUP($A29,'Salary Projections 2026'!$A:$D,2,FALSE) -> 2698 | F29: =D29-E29 -> -2698 | G29: 0 | H29: =VLOOKUP($A29,'Salary Projections 2026'!$A:$D,2,FALSE) -> 2698 | I29: =G29-H29 -> -2698 | J29: 12860 | K29: =VLOOKUP($A29,'Salary Projections 2026'!$A:$D,2,FALSE) -> 2698 | L29: =J29-K29 -> 10162 | M29: 0 | N29: 0 | O29: 0 | P29: 0 | Q29: 0 | R29: 0 | S29: 0 | T29: 0 | U29: 0 | V29: 0 | W29: 0 | X29: 0 | Y29: 0 | Z29: 0 | AA29: 0 | AB29: 0 | AC29: 0 | AD29: 0 | AE29: 0 | AF29: 0 | AG29: 0 | AH29: 0 | AI29: 0 | AJ29: 0 | AK29: 0 | AL29: 0 | AM29: 0 | AN29: {=SUMPRODUCT((D$1:AK$1<>"Margin")*(D$1:AK$1<>"Salary_$600")*D29:AK29)} -> 12860 | AO29: {=SUMPRODUCT((D$1:AM$1="Margin")*D29:AM29)} -> 4766 | AP29: SOW valid until Mar 31, 2026. | AQ29: 0% | AR29: HAL | AS29: DS10_Secured | AU29: 424016 | AV29: 413786 | AW29: 107501
A30: HAL Digital Web Marketing | B30: Neeraj | C30: Staff Aug | D30: 0 | E30: =VLOOKUP($A30,'Salary Projections 2026'!$A:$D,2,FALSE) -> 4478 | F30: =D30-E30 -> -4478 | G30: 0 | H30: =VLOOKUP($A30,'Salary Projections 2026'!$A:$D,2,FALSE) -> 4478 | I30: =G30-H30 -> -4478 | J30: 18900 | K30: =VLOOKUP($A30,'Salary Projections 2026'!$A:$D,2,FALSE) -> 4478 | L30: =J30-K30 -> 14422 | M30: 18000 | N30: =VLOOKUP($A30,'Salary Projections 2026'!$A:$D,3,FALSE) -> 4478 | O30: =M30-N30 -> 13522 | P30: 0 | Q30: =VLOOKUP($A30,'Salary Projections 2026'!$A:$D,3,FALSE) -> 4478 | R30: =P30-Q30 -> -4478 | S30: 0 | T30: =VLOOKUP($A30,'Salary Projections 2026'!$A:$D,3,FALSE) -> 4478 | U30: =S30-T30 -> -4478 | V30: 0 | W30: =VLOOKUP($A30,'Salary Projections 2026'!$A:$D,3,FALSE) -> 4478 | X30: =V30-W30 -> -4478 | Y30: 0 | Z30: =VLOOKUP($A30,'Salary Projections 2026'!$A:$D,3,FALSE) -> 4478 | AA30: =Y30-Z30 -> -4478 | AB30: 18900 | AC30: =VLOOKUP($A30,'Salary Projections 2026'!$A:$D,3,FALSE) -> 4478 | AD30: =AB30-AC30 -> 14422 | AE30: 18000 | AF30: =VLOOKUP($A30,'Salary Projections 2026'!$A:$D,4,FALSE) -> 4478 | AG30: =AE30-AF30 -> 13522 | AH30: 0 | AI30: =VLOOKUP($A30,'Salary Projections 2026'!$A:$D,4,FALSE) -> 4478 | AJ30: =AH30-AI30 -> -4478 | AK30: 0 | AL30: =VLOOKUP($A30,'Salary Projections 2026'!$A:$D,4,FALSE) -> 4478 | AM30: =AK30-AL30 -> -4478 | AN30: {=SUMPRODUCT((D$1:AK$1<>"Margin")*(D$1:AK$1<>"Salary_$600")*D30:AK30)} -> 73800 | AO30: {=SUMPRODUCT((D$1:AM$1="Margin")*D30:AM30)} -> 20064 | AP30: SOW valid until Mar 31, 2026. | AQ30: 100% | AR30: HAL | AS30: DS10_Secured
A31: HAL Marketo Support | B31: Neeraj | C31: Staff Aug | D31: 0 | E31: =VLOOKUP($A31,'Salary Projections 2026'!$A:$D,2,FALSE) -> 2543 | F31: =D31-E31 -> -2543 | G31: 0 | H31: =VLOOKUP($A31,'Salary Projections 2026'!$A:$D,2,FALSE) -> 2543 | I31: =G31-H31 -> -2543 | J31: 16490 | K31: =VLOOKUP($A31,'Salary Projections 2026'!$A:$D,2,FALSE) -> 2543 | L31: =J31-K31 -> 13947 | M31: 0 | N31: 0 | O31: 0 | P31: 0 | Q31: 0 | R31: 0 | S31: 0 | T31: 0 | U31: 0 | V31: 0 | W31: 0 | X31: 0 | Y31: 0 | Z31: 0 | AA31: 0 | AB31: 0 | AC31: 0 | AD31: 0 | AE31: 0 | AF31: 0 | AG31: 0 | AH31: 0 | AI31: 0 | AJ31: 0 | AK31: 0 | AL31: 0 | AM31: 0 | AN31: {=SUMPRODUCT((D$1:AK$1<>"Margin")*(D$1:AK$1<>"Salary_$600")*D31:AK31)} -> 16490 | AO31: {=SUMPRODUCT((D$1:AM$1="Margin")*D31:AM31)} -> 8861 | AP31: SOW valid until Mar 31, 2026. | AQ31: 0% | AR31: HAL | AS31: DS10_Secured
A32: HAL Critical Minerals AI Analysis solution | B32: Neeraj | C32: Project | D32: 0 | E32: 0 | F32: 0 | G32: 0 | H32: 0 | I32: 0 | J32: 22000 | K32: =8950+2933+2881+2915/2+0.1*(J32-8950) -> 17526.5 | L32: =J32-K32 -> 4473.5 | M32: 0 | N32: 0 | O32: 0 | P32: 0 | Q32: 0 | R32: 0 | S32: 0 | T32: 0 | U32: 0 | V32: 0 | W32: 0 | X32: 0 | Y32: 0 | Z32: 0 | AA32: 0 | AB32: 0 | AC32: 0 | AD32: 0 | AE32: 0 | AF32: 0 | AG32: 0 | AH32: 0 | AI32: 0 | AJ32: 0 | AK32: 0 | AL32: 0 | AM32: 0 | AN32: {=SUMPRODUCT((D$1:AK$1<>"Margin")*(D$1:AK$1<>"Salary_$600")*D32:AK32)} -> 22000 | AO32: {=SUMPRODUCT((D$1:AM$1="Margin")*D32:AM32)} -> 4473.5 | AR32: HAL | AS32: DS10_Secured
A33: HAL Marketing Operations Specialist | B33: Neeraj | C33: Project | D33: 0 | F33: 0 | G33: 0 | I33: 0 | J33: 0 | L33: 0 | M33: 0 | O33: 0 | P33: 0 | Q33: =(2300000/12/90+600)*0.25 -> 682.40741 | R33: =P33-Q33 -> -682.40741 | S33: 15000 | T33: =(2300000/12/90+600) -> 2729.6296 | U33: =S33-T33 -> 12270.37 | V33: 0 | W33: =(2300000/12/90+600) -> 2729.6296 | X33: =V33-W33 -> -2729.6296 | Y33: 0 | Z33: =(2300000/12/90+600) -> 2729.6296 | AA33: =Y33-Z33 -> -2729.6296 | AB33: 0 | AC33: =(2300000/12/90+600) -> 2729.6296 | AD33: =AB33-AC33 -> -2729.6296 | AE33: 15000 | AF33: =(2300000/12/90+600) -> 2729.6296 | AG33: =AE33-AF33 -> 12270.37 | AH33: 0 | AI33: =(2300000/12/90+600) -> 2729.6296 | AJ33: =AH33-AI33 -> -2729.6296 | AK33: 15000 | AL33: =(2300000/12/90+600) -> 2729.6296 | AM33: =AK33-AL33 -> 12270.37 | AN33: {=SUMPRODUCT((D$1:AK$1<>"Margin")*(D$1:AK$1<>"Salary_$600")*D33:AK33)} -> 45000 | AO33: {=SUMPRODUCT((D$1:AM$1="Margin")*D33:AM33)} -> 25210.185 | AP33: Started this new in May 2026 | AQ33: 100% | AR33: HAL | AS33: DS10_Secured
A34: Business Travel of Abhishek Kalsy to Las Vegas for Hitachi Americas Brand and Growth | B34: Neeraj | C34: Project | E34: 0 | F34: 0 | G34: 0 | H34: 0 | I34: 0 | J34: 0 | K34: 0 | L34: 0 | M34: 0 | N34: 0 | O34: 0 | P34: 0 | Q34: 0 | R34: 0 | S34: 7950 | T34: 7950 | U34: 0 | V34: 0 | W34: 0 | X34: 0 | Y34: 0 | Z34: 0 | AA34: 0 | AB34: 0 | AC34: 0 | AD34: 0 | AE34: 0 | AF34: 0 | AG34: 0 | AH34: 0 | AI34: 0 | AJ34: 0 | AK34: 0 | AL34: 0 | AM34: 9 | AN34: {=SUMPRODUCT((D$1:AK$1<>"Margin")*(D$1:AK$1<>"Salary_$600")*D34:AK34)} -> 7950 | AO34: {=SUMPRODUCT((D$1:AM$1="Margin")*D34:AM34)} -> 9 | AR34: HAL | AS34: DS10_Secured
A35: Hitachi ByState Enhancement | B35: Neeraj | C35: Project | D35: 0 | E35: 0 | F35: 0 | G35: 0 | H35: 0 | I35: 0 | J35: 3000 | K35: 1741 | L35: =J35-K35 -> 1259 | M35: 0 | N35: 0 | O35: 0 | P35: 0 | Q35: 0 | R35: 0 | S35: 0 | T35: 0 | U35: 0 | V35: 0 | W35: 0 | X35: 0 | Y35: 0 | Z35: 0 | AA35: 0 | AB35: 0 | AC35: 0 | AD35: 0 | AE35: 0 | AF35: 0 | AG35: 0 | AH35: 0 | AI35: 0 | AJ35: 0 | AK35: 0 | AL35: 0 | AM35: 0 | AN35: {=SUMPRODUCT((D$1:AK$1<>"Margin")*(D$1:AK$1<>"Salary_$600")*D35:AK35)} -> 3000 | AO35: {=SUMPRODUCT((D$1:AM$1="Margin")*D35:AM35)} -> 1259 | AR35: HAL | AS35: DS10_Secured
A36: Hitachi Stem - Development Support | B36: Neeraj | C36: Staff Aug | D36: 5250 | E36: =VLOOKUP($A36,'Salary Projections 2026'!$A:$D,2,FALSE) -> 3015 | F36: =D36-E36 -> 2235 | G36: 4000 | H36: =VLOOKUP($A36,'Salary Projections 2026'!$A:$D,2,FALSE) -> 3015 | I36: =G36-H36 -> 985 | J36: 4000 | K36: =VLOOKUP($A36,'Salary Projections 2026'!$A:$D,2,FALSE) -> 3015 | L36: =J36-K36 -> 985 | M36: 4000 | N36: =VLOOKUP($A36,'Salary Projections 2026'!$A:$D,3,FALSE) -> 3015 | O36: =M36-N36 -> 985 | P36: 4000 | Q36: =VLOOKUP($A36,'Salary Projections 2026'!$A:$D,3,FALSE) -> 3015 | R36: =P36-Q36 -> 985 | S36: 4000 | T36: =VLOOKUP($A36,'Salary Projections 2026'!$A:$D,3,FALSE) -> 3015 | U36: =S36-T36 -> 985 | V36: 4000 | W36: =VLOOKUP($A36,'Salary Projections 2026'!$A:$D,3,FALSE) -> 3015 | X36: =V36-W36 -> 985 | Y36: 4000 | Z36: =VLOOKUP($A36,'Salary Projections 2026'!$A:$D,3,FALSE) -> 3015 | AA36: =Y36-Z36 -> 985 | AB36: 4000 | AC36: =VLOOKUP($A36,'Salary Projections 2026'!$A:$D,3,FALSE) -> 3015 | AD36: =AB36-AC36 -> 985 | AE36: 4000 | AF36: =VLOOKUP($A36,'Salary Projections 2026'!$A:$D,4,FALSE) -> 3015 | AG36: =AE36-AF36 -> 985 | AH36: 4000 | AI36: =VLOOKUP($A36,'Salary Projections 2026'!$A:$D,4,FALSE) -> 3015 | AJ36: =AH36-AI36 -> 985 | AK36: 4000 | AL36: =VLOOKUP($A36,'Salary Projections 2026'!$A:$D,4,FALSE) -> 3015 | AM36: =AK36-AL36 -> 985 | AN36: {=SUMPRODUCT((D$1:AK$1<>"Margin")*(D$1:AK$1<>"Salary_$600")*D36:AK36)} -> 49250 | AO36: {=SUMPRODUCT((D$1:AM$1="Margin")*D36:AM36)} -> 13070 | AP36: Open Ended SOW | AQ36: 100% | AR36: Hitachi Stem | AS36: DS10_Secured
A37: HPE SEO PM HPE Store Hament Dudeja | B37: Neeraj | C37: Staff Aug | D37: =16800/4 -> 4200 | E37: =VLOOKUP($A37,'Salary Projections 2026'!$A:$D,2,FALSE) -> 748 | F37: =D37-E37 -> 3452 | G37: 0 | H37: =VLOOKUP($A37,'Salary Projections 2026'!$A:$D,2,FALSE) -> 748 | I37: =G37-H37 -> -748 | J37: 0 | K37: =VLOOKUP($A37,'Salary Projections 2026'!$A:$D,2,FALSE) -> 748 | L37: =J37-K37 -> -748 | M37: =16800/4 -> 4200 | N37: =VLOOKUP($A37,'Salary Projections 2026'!$A:$D,3,FALSE) -> 748 | O37: =M37-N37 -> 3452 | P37: 0 | Q37: =VLOOKUP($A37,'Salary Projections 2026'!$A:$D,3,FALSE) -> 748 | R37: =P37-Q37 -> -748 | S37: 0 | T37: =VLOOKUP($A37,'Salary Projections 2026'!$A:$D,3,FALSE) -> 748 | U37: =S37-T37 -> -748 | V37: =16800/4 -> 4200 | W37: =VLOOKUP($A37,'Salary Projections 2026'!$A:$D,3,FALSE) -> 748 | X37: =V37-W37 -> 3452 | Y37: 0 | Z37: =VLOOKUP($A37,'Salary Projections 2026'!$A:$D,3,FALSE) -> 748 | AA37: =Y37-Z37 -> -748 | AB37: 0 | AC37: =VLOOKUP($A37,'Salary Projections 2026'!$A:$D,3,FALSE) -> 748 | AD37: =AB37-AC37 -> -748 | AE37: =16800/4 -> 4200 | AF37: =VLOOKUP($A37,'Salary Projections 2026'!$A:$D,4,FALSE) -> 748 | AG37: =AE37-AF37 -> 3452 | AH37: 0 | AI37: =VLOOKUP($A37,'Salary Projections 2026'!$A:$D,4,FALSE) -> 748 | AJ37: =AH37-AI37 -> -748 | AK37: 0 | AL37: =VLOOKUP($A37,'Salary Projections 2026'!$A:$D,4,FALSE) -> 748 | AM37: =AK37-AL37 -> -748 | AN37: {=SUMPRODUCT((D$1:AK$1<>"Margin")*(D$1:AK$1<>"Salary_$600")*D37:AK37)} -> 16800 | AO37: {=SUMPRODUCT((D$1:AM$1="Margin")*D37:AM37)} -> 7824 | AP37: SOW valid until Oct 31, 2026 | AQ37: 100% | AR37: HPE | AS37: DS10_Secured | AU37: 829892 | AV37: 911397 | AW37: 216343
A38: HPE Marketing Strategy & Operations for the APJ Region | B38: Neeraj | C38: Staff Aug | D38: 5040 | E38: =VLOOKUP($A38,'Salary Projections 2026'!$A:$D,2,FALSE) -> 4802 | F38: =D38-E38 -> 238 | G38: 5600 | H38: =VLOOKUP($A38,'Salary Projections 2026'!$A:$D,2,FALSE) -> 4802 | I38: =G38-H38 -> 798 | J38: 5880 | K38: =VLOOKUP($A38,'Salary Projections 2026'!$A:$D,2,FALSE) -> 4802 | L38: =J38-K38 -> 1078 | M38: =1*35*'Working Days'!$C$5 -> 6160 | N38: =VLOOKUP($A38,'Salary Projections 2026'!$A:$D,3,FALSE) -> 4802 | O38: =M38-N38 -> 1358 | P38: 5600 | Q38: =VLOOKUP($A38,'Salary Projections 2026'!$A:$D,3,FALSE) -> 4802 | R38: =P38-Q38 -> 798 | S38: =1*35*'Working Days'!$C$7 -> 5880 | T38: =VLOOKUP($A38,'Salary Projections 2026'!$A:$D,3,FALSE) -> 4802 | U38: =S38-T38 -> 1078 | V38: =1*35*'Working Days'!$C$8 -> 6440 | W38: =VLOOKUP($A38,'Salary Projections 2026'!$A:$D,3,FALSE) -> 4802 | X38: =V38-W38 -> 1638 | Y38: =1*35*'Working Days'!$C$9 -> 5600 | Z38: =VLOOKUP($A38,'Salary Projections 2026'!$A:$D,3,FALSE) -> 4802 | AA38: =Y38-Z38 -> 798 | AB38: =1*35*'Working Days'!$C$10 -> 6160 | AC38: =VLOOKUP($A38,'Salary Projections 2026'!$A:$D,3,FALSE) -> 4802 | AD38: =AB38-AC38 -> 1358 | AE38: =1*35*'Working Days'!$C$11 -> 5600 | AF38: =VLOOKUP($A38,'Salary Projections 2026'!$A:$D,4,FALSE) -> 4802 | AG38: =AE38-AF38 -> 798 | AH38: =1*35*'Working Days'!$C$12 -> 5320 | AI38: =VLOOKUP($A38,'Salary Projections 2026'!$A:$D,4,FALSE) -> 4802 | AJ38: =AH38-AI38 -> 518 | AK38: =1*35*'Working Days'!$C$13 -> 4760 | AL38: =VLOOKUP($A38,'Salary Projections 2026'!$A:$D,4,FALSE) -> 4802 | AM38: =AK38-AL38 -> -42 | AN38: {=SUMPRODUCT((D$1:AK$1<>"Margin")*(D$1:AK$1<>"Salary_$600")*D38:AK38)} -> 68040 | AO38: {=SUMPRODUCT((D$1:AM$1="Margin")*D38:AM38)} -> 10416 | AP38: SOW valid until Oct 31, 2026 | AQ38: 100% | AR38: HPE | AS38: DS10_Secured
A39: HPE Data Foundations Shashidhar Iddamsetty | B39: Neeraj | C39: Staff Aug | D39: 11200 | E39: =VLOOKUP($A39,'Salary Projections 2026'!$A:$D,2,FALSE) -> 6597 | F39: =D39-E39 -> 4603 | G39: 10080 | H39: =VLOOKUP($A39,'Salary Projections 2026'!$A:$D,2,FALSE) -> 6597 | I39: =G39-H39 -> 3483 | J39: 11340 | K39: =VLOOKUP($A39,'Salary Projections 2026'!$A:$D,2,FALSE) -> 6597 | L39: =J39-K39 -> 4743 | M39: 11480 | N39: =VLOOKUP($A39,'Salary Projections 2026'!$A:$D,3,FALSE)+2265 -> 6598 | O39: =M39-N39 -> 4882 | P39: 7280 | Q39: =VLOOKUP($A39,'Salary Projections 2026'!$A:$D,3,FALSE) -> 4333 | R39: =P39-Q39 -> 2947 | S39: 5880 | T39: =VLOOKUP($A39,'Salary Projections 2026'!$A:$D,3,FALSE) -> 4333 | U39: =S39-T39 -> 1547 | V39: 5880 | W39: =VLOOKUP($A39,'Salary Projections 2026'!$A:$D,3,FALSE) -> 4333 | X39: =V39-W39 -> 1547 | Y39: 5880 | Z39: =VLOOKUP($A39,'Salary Projections 2026'!$A:$D,3,FALSE) -> 4333 | AA39: =Y39-Z39 -> 1547 | AB39: 5880 | AC39: =VLOOKUP($A39,'Salary Projections 2026'!$A:$D,3,FALSE) -> 4333 | AD39: =AB39-AC39 -> 1547 | AE39: 5880 | AF39: =VLOOKUP($A39,'Salary Projections 2026'!$A:$D,4,FALSE) -> 4333 | AG39: =AE39-AF39 -> 1547 | AH39: 5880 | AI39: =VLOOKUP($A39,'Salary Projections 2026'!$A:$D,4,FALSE) -> 4333 | AJ39: =AH39-AI39 -> 1547 | AK39: 5880 | AL39: =VLOOKUP($A39,'Salary Projections 2026'!$A:$D,4,FALSE) -> 4333 | AM39: =AK39-AL39 -> 1547 | AN39: {=SUMPRODUCT((D$1:AK$1<>"Margin")*(D$1:AK$1<>"Salary_$600")*D39:AK39)} -> 92540 | AO39: {=SUMPRODUCT((D$1:AM$1="Margin")*D39:AM39)} -> 31487 | AP39: SOW valid until Jan 31, 2026. | AQ39: 100% | AR39: HPE | AS39: DS10_Secured
A40: HPE Marketing Automation- Christian Voigt | B40: Neeraj | C40: Staff Aug | D40: 9240 | E40: =VLOOKUP($A40,'Salary Projections 2026'!$A:$D,2,FALSE) -> 7591 | F40: =D40-E40 -> 1649 | G40: 11200 | H40: =VLOOKUP($A40,'Salary Projections 2026'!$A:$D,2,FALSE) -> 7591 | I40: =G40-H40 -> 3609 | J40: 12320 | K40: =VLOOKUP($A40,'Salary Projections 2026'!$A:$D,2,FALSE) -> 7591 | L40: =J40-K40 -> 4729 | M40: 10640 | N40: =VLOOKUP($A40,'Salary Projections 2026'!$A:$D,3,FALSE) -> 7591 | O40: =M40-N40 -> 3049 | P40: 10080 | Q40: =VLOOKUP($A40,'Salary Projections 2026'!$A:$D,3,FALSE) -> 7591 | R40: =P40-Q40 -> 2489 | S40: =5880*2 -> 11760 | T40: =VLOOKUP($A40,'Salary Projections 2026'!$A:$D,3,FALSE) -> 7591 | U40: =S40-T40 -> 4169 | V40: =5880*2 -> 11760 | W40: =VLOOKUP($A40,'Salary Projections 2026'!$A:$D,3,FALSE) -> 7591 | X40: =V40-W40 -> 4169 | Y40: =5880*2 -> 11760 | Z40: =VLOOKUP($A40,'Salary Projections 2026'!$A:$D,3,FALSE) -> 7591 | AA40: =Y40-Z40 -> 4169 | AB40: =5880*2 -> 11760 | AC40: =VLOOKUP($A40,'Salary Projections 2026'!$A:$D,3,FALSE) -> 7591 | AD40: =AB40-AC40 -> 4169 | AE40: =5880*2 -> 11760 | AF40: =VLOOKUP($A40,'Salary Projections 2026'!$A:$D,4,FALSE) -> 7591 | AG40: =AE40-AF40 -> 4169 | AH40: =5880*2 -> 11760 | AI40: =VLOOKUP($A40,'Salary Projections 2026'!$A:$D,4,FALSE) -> 7591 | AJ40: =AH40-AI40 -> 4169 | AK40: =5880*2 -> 11760 | AL40: =VLOOKUP($A40,'Salary Projections 2026'!$A:$D,4,FALSE) -> 7591 | AM40: =AK40-AL40 -> 4169 | AN40: {=SUMPRODUCT((D$1:AK$1<>"Margin")*(D$1:AK$1<>"Salary_$600")*D40:AK40)} -> 135800 | AO40: {=SUMPRODUCT((D$1:AM$1="Margin")*D40:AM40)} -> 44708 | AP40: SOW valid until Jan 31, 2026. | AQ40: 100% | AR40: HPE | AS40: DS10_Secured
...

Sheet 2026_ClientComments
A1: Group | B1: Client List | C1: Confidence | D1: Comments
A2: DS10_Secured | B2: Automation Anywhere | C2: 100% | D2: Renewal SOW approved for 1. 6-month duration until July 2026 2. Team size reduced from current 10 to 9 resources 3. Monthly billing $30,000 SOW for period Aug - Oct 2026 submitted for approval
A3: DS10_Secured | B3: AIS Solutions | C3: 0% | D3: Opened the account with 1 full time FED for 3 months. Client is not going to renew this account post May 15
A4: DS10_Secured | B4: Aldevron | C4: 100% | D4: Initiated engagement with the client through a small project valued at $1,200. Successfully secured an ongoing maintenance SOW worth $8,150 per month, with a start date of February 2, 2026.
A5: DS10_Secured | B5: CheckPoint | C5: 0% | D5: The client has discontinued our services from April onwards.
A6: DS10_Secured | B6: Churchs-Chicken | C6: 100% | D6: SOW valid until Dec 31, 2027.
A7: DS10_Secured | B7: Databricks | C7: 100% | D7: We have 6 active SOWs with Databricks. 1. The Website maintenance SOW with monthly billing of ~$66,300 is approved until Sep 30, 2026 2. The rest of the SOWs are approved with a total monthly billing of ~$115,000 and approved until April 30, 2026. The SOWs are a. SEO Content Strategist b. SEO Program Management (This position is now being moved to the US. We are working with the client on identifying an appropriate resource. Interviews in progress. c. Planning Project d. Martech Platform Operations e. Program Manager and Marketo
A8: DS10_Secured | B8: Doppel | C8: 25% | D8: Secured a maintenance SOW for $4,200 a month with a start date of Feb 2, 2026. We have been following up with the client on tasks since Feb 1, but we haven't received a response.
A9: DS10_Secured | B9: EGIA | C9: 100% | D9: Open-ended SOW for the last many of years. Growth in 2026 is expected as EGIA wins more RFPs
A10: DS10_Secured | B10: HAL | C10: 100% | D10: 1. We started 2026 with 3 Staff Augmentation SOWs. Two of these SOW (Creative and Marketo) were discontinued from April 2026 and were left with "Digital Web Marketing" SOW, which is approved until Sep 2026 ($36,900 for 6 months) and has high confidence in getting it further renewed. 2. Signed a new SOW for Digital Marketing Operation Specialist $5000/month. Start date May 18 3. Delivered a fixed cost project, "Critical Minerals AI Analysis solution," for $22,000.
A11: DS10_Secured | B11: Hitachi Asia | C11: 75% | D11: The client visited our India office on May 6- 7 to go over the 2026 projects. Client agreed on 4 proposals and the same have been submitted for approval with a total billing value of $93K. Another AI project proposal has been submitted for approval Phase 1 - Pilot: INR 9,95,500 Phase 2 - full rollout: INR 7,53,300 + monthly subscription of $2,500
A12: DS10_Secured | B12: Hitachi Stem | C12: 100% | D12: Open Ended SOW
... A20: DS10_Secured | B20: YetiMyFriend | C20: 100% | D20: Open-ended SOW.
A22: DS10_Secured | B22: AI Forward
A23: DS10_Secured | B23: Bench
A24: DS10_Secured | B24: Bench Deployed
A25: DS10_Secured | B25: MetaSys Payroll Portal-Truist
A26: DS10_Secured | B26: MetaSys Staffing Reports Wendy
A27: DS10_Secured | B27: MetaSys, Marlow Content and Design
A28: DS10_Secured | B28: Ovis Programming + MetaSys Websites
A29: DS10_Secured | B29: Ovis- Creative Support
A30: DS10_Secured | B30: Sales & Marketing (Nvish & MetaSys)
A35: DS30_Projection | B35: HAL | C35: 50% | D35: Proposal submitted in Dec 2025. Client has come back with feedback. Updated proposal will be shared with client in the week of Jan 18.
A36: DS30_Projection | B36: Hitachi Asia | C36: 50% | D36: Client is visit India Office on May 6,7 to discuss projects
A37: DS30_Projection | B37: IDBS | C37: 75% | D37: Signed a Help-Center project for $53,900 with go-live Sep 25, 2026 Working to win additional SOW for Website enhacements
A38: DS30_Projection | B38: NorthWest Storage | C38: 25% | D38: Discussions pushed till Jan 2026
A39: DS30_Projection
A44: DS50_Projection | B44: ADNOC | C44: 25% | D44: Top-of-funnel activities - Working with Ankur Rana
A45: DS50_Projection | B45: Alliance Technical Group | C45: 5% | D45: Raghu is working with Romeen to move this
A46: DS50_Projection | B46: Anurag | C46: 75%
A47: DS50_Projection | B47: Fannie Mae | C47: 5% | D47: Fannie Mae RFP being developed in collaboration with OSG. On hold for now
A48: DS50_Projection | B48: GIZ - I | C48: 75% | D48: RFP response submitted - Working with Ankur Rana
A49: DS50_Projection | B49: GIZ - II | C49: 75% | D49: RFP response submitted - Working with Ankur Rana
A50: DS50_Projection | B50: IHG | C50: 25% | D50: Request sent to Raj Verma to follow up with Vivien. In addition to this met with Ketan through Ankur Rana
A51: DS50_Projection | B51: Inatech | C51: 25% | D51: Top-of-funnel activities. Ram working with Raghu to discuss the options
A52: DS50_Projection | B52: Miller Knoll | C52: 50% | D52: POC approach dropped. Raghu and Raj met the Millet Knoll at Miami and will make it moving
A53: DS50_Projection | B53: OSG - Castrol | C53: 50%
A54: DS50_Projection | B54: OSG - Dewsy | C54: 25%
A55: DS50_Projection | B55: OSG - DHA | C55: 25%
A56: DS50_Projection | B56: OSG - DHA TB | C56: 25%
...

Sheet Sales by Customer- 2025
A1: NVISH Solutions Inc.
A2: Sales by Customer Summary
A3: Green: Legacy account Green background with approved SOW Blue not yet approved but confidence high
A4: Blue: Legacy Account with Growth,
A5: Yellow: New Logo with jobs, Orange: Pipeline
A7: Name | B7: POC | C7: LOB | D7: Jan_Act | E7: Jan_Sal | F7: Jan_Mar | G7: Feb_Act | H7: Feb_Sal | I7: Feb_Mar | J7: Mar_Act | K7: Mar_Sal | L7: Mar_Mar | M7: Apr_Act | N7: Apr_Sal | O7: Apr_Mar | P7: May_Act | Q7: May_Sal | R7: May_Mar | S7: Jun_Act | T7: Jun_Sal | U7: Jun_Mar | V7: Jul_Act | W7: Jul_Sal | X7: Jul_Mar | Y7: Aug_Act | Z7: Aug_Sal | AA7: Aug_Mar | AB7: Sep_Act | AC7: Sep_Sal | AD7: Sep_Mar | AE7: Oct_Act | AF7: Oct_Sal | AG7: Oct_Mar | AH7: Nov_Act | AI7: Nov_Sal | AJ7: Nov_Mar | AK7: Dec_Act | AL7: Dec_Sal | AM7: Dec_Mar | AN7: Total_Rev | AO7: Total_NM | AP7: Comments | AQ7: Renewal Confidence | AR7: Project Id | AS7: Group | AT7: Notes
D8: Actual | E8: Salary_$600 | F8: Margin | G8: Actual | H8: Salary_$600 | I8: Margin | J8: Actual | K8: Salary_$600 | L8: Margin | M8: Actual | N8: Salary_$600 | O8: Margin | P8: Actuals | Q8: Salary_$600 | R8: Margin | S8: Actual | T8: Salary_$600 | U8: Margin | V8: Actual | W8: Salary_$600 | X8: Margin | Y8: Actual | Z8: Salary_$600 | AA8: Margin | AB8: Actual | AC8: Salary_$600 | AD8: Margin | AE8: Actual | AF8: Salary_$600 | AG8: Margin | AH8: Actual | AI8: Salary_$600 | AJ8: Margin | AK8: Actual | AL8: Salary_$600 | AM8: Margin
